error:
… from call site

  at ./default.nix:396:16:

   395|
   396|       giving = callPackage ./pkgs/python3/pkgs/giving { };
      |                ^
   397|

… while calling 'callPackageWith'

  at <nixpkgs> + /lib/customisation.nix:212:35:

   211|   */
   212|   callPackageWith = autoArgs: fn: args:
      |                                   ^
   213|     let

error: evaluation aborted with the following error message: 'lib.customisation.callPackageWith: Function called without required argument "varname" at ./pkgs/python3/pkgs/giving/default.nix:7'
